<?xml version="1.0" ?>

<robot name="ruka_gz">


    <material name="white">
        <color rgba="1 1 1 1"/>
    </material>

    <material name="red">
        <color rgba="1 0 0 1"/>
    </material>

    <link name="base_link">

        <inertial>
            <mass value="2.0"/>
            <origin rpy="0 0 0" xyz="-0.025566 -2.88e-05 0.057332"/>
            <inertia ixx="0.00782229414331" ixy="0.0" ixz="0.0" iyy="0.0109027971813" iyz="0.0" izz="0.0102355503949"/>
        </inertial>

        <visual>
          <origin rpy="0 0 0" xyz="0 0 0.015" />
          <geometry>
            <cylinder radius="0.09" length="0.03" />
          </geometry>

        <material name="white"/>
        </visual>

        <collision>
            <origin rpy="0 0 0" xyz="0 0 0.015" />
          <geometry>
            <cylinder radius="0.09" length="0.03" />
          </geometry>
          </collision>

    </link>

    <joint name="base_link__link_01" type="revolute">
        <axis xyz="0 0 1"/>

        <safety_controller k_position="100.0" k_velocity="40.0" soft_lower_limit="-2.908" soft_upper_limit="2.908" />

        <limit effort="1000.0" lower="-2.96" upper="2.96" velocity="0.5"/>
        <origin rpy="0 0 0" xyz="0 0 0.03"/>
        <parent link="base_link"/>
        <child link="link_01"/>

    </joint>

    <link name="link_01">


        <inertial>
            <mass value="2.0"/>
            <origin rpy="0 0 0" xyz="0 -0.0324958 -0.0675818"/>
            <inertia ixx="0.0180416958283" ixy="0.0" ixz="0.0" iyy="0.0159136071891" iyz="0.0" izz="0.00620690827127"/>
        </inertial>

        <visual>
            <origin rpy="0 0 0" xyz="0 0 0.016" />
            <geometry>
                <cylinder radius="0.047" length="0.032" />
            </geometry>
            <material name="white"/>

        </visual>

        <collision>
            <origin rpy="0 0 0" xyz="0 0 0.016" />
            <geometry>
                <cylinder radius="0.047" length="0.032" />
            </geometry>
          </collision>

        <visual>
            <origin rpy="0 0 0" xyz="-0.0365 0 0.085" />
            <geometry>
                <box size ="0.173 0.148 0.106"/>
            </geometry>
             <material name="white"/>

        </visual>

        <collision>
           <origin rpy="0 0 0" xyz="-0.0365 0 0.085" />
            <geometry>
                <box size ="0.173 0.148 0.106"/>
            </geometry>
          </collision>

    </link>

    <joint name="link_01__link_01_red" type="fixed">
        <origin rpy="0 0 0" xyz="0.01 0 0"/>
        <parent link="link_01"/>
        <child link="link_01_red"/>
    </joint>

    <link name="link_01_red">
        <visual>
            <origin rpy="0 0 0" xyz="0 0.088 0.1115" />
            <geometry>
                <box size ="0.08 0.028 0.135"/>
            </geometry>
            <material name="red"/>

        </visual>

        <collision>
            <origin rpy="0 0 0" xyz="0 0.088 0.1115" />
            <geometry>
                <box size ="0.08 0.028 0.135"/>
            </geometry>
          </collision>

        <visual>
            <origin rpy="0 0 0" xyz="0 -0.088 0.1115" />
            <geometry>
                <box size ="0.08 0.028 0.135"/>
            </geometry>
            <material name="red"/>

        </visual>

        <collision>
            <origin rpy="0 0 0" xyz="0 -0.088 0.1115" />
            <geometry>
                <box size ="0.08 0.028 0.135"/>
            </geometry>
          </collision>

        <visual>
            <origin rpy="1.57 0 0" xyz="0 -0.088 0.179" />
            <geometry>
                <cylinder radius="0.04" length="0.028"/>
            </geometry>
            <material name="red"/>

        </visual>

        <collision>
           <origin rpy="1.57 0 0" xyz="0 -0.088 0.179" />
            <geometry>
                <cylinder radius="0.04" length="0.028"/>
            </geometry>
          </collision>

        <visual>
            <origin rpy="1.57 0 0" xyz="0 0.088 0.179" />
            <geometry>
                <cylinder radius="0.04" length="0.028"/>
            </geometry>
            <material name="red"/>

        </visual>

        <collision>
           <origin rpy="1.57 0 0" xyz="0 0.088 0.179" />
            <geometry>
                <cylinder radius="0.04" length="0.028"/>
            </geometry>
          </collision>
    </link>

    <joint name="link_01__link_02" type="revolute">
        <axis xyz="0 0 1"/>

        <safety_controller k_position="100.0" k_velocity="40.0" soft_lower_limit="-3.518" soft_upper_limit="0.1" />

        <limit effort="1000.0" lower="-3.57" upper="0.05" velocity="0.5"/>
        <origin rpy="1.57 -1.57 0" xyz="0.01 0 0.179"/>   <!-- origin rpy="1.57 0 0"-->
        <parent link="link_01"/>

        <child link="link_02"/>
    </joint>

    <link name="link_02">

       <inertial>
            <mass value="1.5"/>
            <origin rpy="0 0 0" xyz="0 -0.06861 0.0322285"/>
             <inertia ixx="0.0182856182281" ixy="0.0" ixz="0.0" iyy="0.00621358421175" iyz="-0.00472844221905" izz="0.0161514346309"/>
        </inertial>

        <visual>
            <origin rpy="0 0 0" xyz="0 0 0" />
            <geometry>
                <cylinder radius="0.038" length="0.148"/>
            </geometry>
            <material name="white"/>

        </visual>

        <collision>
             <origin rpy="0 0 0" xyz="0 0 0" />
            <geometry>
                <cylinder radius="0.038" length="0.148"/>
            </geometry>
          </collision>

        <visual>
            <origin rpy="0 0 0" xyz="0 0.06775 0" />
            <geometry>
                <box size ="0.076 0.1355 0.116"/>
            </geometry>
            <material name="white"/>

        </visual>

        <collision>
          <origin rpy="0 0 0" xyz="0 0.06775 0" />
            <geometry>
                <box size ="0.076 0.1355 0.116"/>
            </geometry>
          </collision>

        <visual>
            <origin rpy="0 1.57 0" xyz="0 0.14 0.055" />
            <geometry>
                <box size ="0.006 0.28 0.076"/>
            </geometry>
            <material name="white"/>

        </visual>

        <collision>
            <origin rpy="0 1.57 0" xyz="0 0.14 0.055" />
            <geometry>
                <box size ="0.006 0.28 0.076"/>
            </geometry>
          </collision>

        <visual>
            <origin rpy="0 1.57 0" xyz="0 0.14 -0.055" />
            <geometry>
                <box size ="0.006 0.28 0.076"/>
            </geometry>
            <material name="white"/>

        </visual>

        <collision>
            <origin rpy="0 1.57 0" xyz="0 0.14 -0.055" />
            <geometry>
                <box size ="0.006 0.28 0.076"/>
            </geometry>
          </collision>

        <visual>
            <origin rpy="0 0 0" xyz="0 0.28 -0.055" />
            <geometry>
                <cylinder radius="0.038" length="0.006"/>
            </geometry>
            <material name="white"/>

        </visual>

        <collision>
            <origin rpy="0 0 0" xyz="0 0.28 -0.055" />
            <geometry>
                <cylinder radius="0.038" length="0.006"/>
            </geometry>
          </collision>

        <visual>
            <origin rpy="0 0 0" xyz="0 0.28 0.055" />
            <geometry>
                <cylinder radius="0.038" length="0.006"/>
            </geometry>
            <material name="white"/>

        </visual>

        <collision>
            <origin rpy="0 0 0" xyz="0 0.28 0.055" />
            <geometry>
                <cylinder radius="0.038" length="0.006"/>
            </geometry>
          </collision>

    </link>

    <joint name="link_02__link_02_red" type="fixed">
        <origin rpy="0 0 0" xyz="0 0.181 0"/>
        <parent link="link_02"/>
        <child link="link_02_red"/>
    </joint>

    <link name="link_02_red">
        <visual>
            <origin rpy="0 0 0" xyz="0 0 0.0705" />
            <geometry>
                <box size ="0.076 0.198 0.025"/>
            </geometry>
            <material name="red"/>

        </visual>

        <collision>
            <origin rpy="0 0 0" xyz="0 0 0.0705" />
            <geometry>
                <box size ="0.076 0.198 0.025"/>
            </geometry>
          </collision>

        <visual>
            <origin rpy="0 0 0" xyz="0 0 -0.0705" />
            <geometry>
                <box size ="0.076 0.198 0.025"/>
            </geometry>
            <material name="red"/>

        </visual>

        <collision>
            <origin rpy="0 0 0" xyz="0 0 -0.0705" />
            <geometry>
                <box size ="0.076 0.198 0.025"/>
            </geometry>
          </collision>

        <visual>
            <origin rpy="0 0 0" xyz="0 -0.099 0.0705" />
            <geometry>
                <cylinder radius="0.038" length="0.025"/>
            </geometry>
            <material name="red"/>

        </visual>

        <collision>
            <origin rpy="0 0 0" xyz="0 -0.099 0.0705" />
            <geometry>
                <cylinder radius="0.038" length="0.025"/>
            </geometry>

          </collision>

        <visual>
            <origin rpy="0 0 0" xyz="0 0.099 0.0705" />
            <geometry>
                <cylinder radius="0.038" length="0.025"/>
            </geometry>
            <material name="red"/>

        </visual>

        <collision>
            <origin rpy="0 0 0" xyz="0 0.099 0.0705" />
            <geometry>
                <cylinder radius="0.038" length="0.025"/>
            </geometry>
          </collision>

        <visual>
            <origin rpy="0 0 0" xyz="0 -0.099 -0.0705" />
            <geometry>
                <cylinder radius="0.038" length="0.025"/>
            </geometry>
            <material name="red"/>

        </visual>

        <collision>
            <origin rpy="0 0 0" xyz="0 -0.099 -0.0705" />
            <geometry>
                <cylinder radius="0.038" length="0.025"/>
            </geometry>
          </collision>

        <visual>
            <origin rpy="0 0 0" xyz="0 0.099 -0.0705" />
            <geometry>
                <cylinder radius="0.038" length="0.025"/>
            </geometry>
            <material name="red"/>

        </visual>

        <collision>
             <origin rpy="0 0 0" xyz="0 0.099 -0.0705" />
            <geometry>
                <cylinder radius="0.038" length="0.025"/>
            </geometry>

          </collision>

    </link>

    <joint name="link_02__link_03" type="revolute">
        <axis xyz="0 0 1"/>

        <!-- <safety_controller k_position="100.0" k_velocity="40.0" soft_lower_limit="0.067" soft_upper_limit="5.178" /> -->

        <limit effort="1000.0" lower="-0.035" upper="5.23" velocity="0.5"/>
        <origin rpy="0 0 0.0175" xyz="0 0.28 0"/>
        <!-- !!!!!!!!!!!!!!!!!!!!! /> -->
        <parent link="link_02"/>
        <child link="link_03"/>
    </joint>

    <link name="link_03">

         <inertial>
            <mass value="1.0"/>
            <origin rpy="0 0 0" xyz="0.0469893 0.0316374 -0.031704"/>
            <inertia ixx="0.00771376630908" ixy="0.0" ixz="0.0" iyy="0.00989108008727" iyz="0.0" izz="0.005"/>
        </inertial>
        <visual>
            <origin rpy="0 0 0" xyz="0 0 0" />
            <geometry>
                <cylinder radius="0.019" length="0.104" />
            </geometry>
            <material name="white"/>
        </visual>

        <collision>
            <origin rpy="0 0 0" xyz="0 0 0" />
            <geometry>
                <cylinder radius="0.019" length="0.104" />
            </geometry>
          </collision>

        <visual>
            <origin rpy="0 0 0" xyz="0.04 0 0" />
            <geometry>
                <box size ="0.120 0.090 0.08"/>
            </geometry>
             <material name="white"/>

        </visual>

        <collision>
            <origin rpy="0 0 0" xyz="0.04 0 0" />
            <geometry>
                <box size ="0.120 0.090 0.08"/>
            </geometry>
          </collision>

    </link>

    <joint name="link_03__link_03_red" type="fixed">
        <origin rpy="0 0 0" xyz="0.04 0 0"/>
        <parent link="link_03"/>
        <child link="link_03_red"/>
    </joint>


    <link name="link_03_red">

       <visual>
            <origin rpy="0 0 0" xyz="0 0.05 0" />
            <geometry>
                <box size ="0.120 0.020 0.08"/>
            </geometry>
            <material name="red"/>

        </visual>

        <collision>
           <origin rpy="0 0 0" xyz="0 0.05 0" />
            <geometry>
                <box size ="0.120 0.020 0.08"/>
            </geometry>
          </collision>

        <visual>
            <origin rpy="0 0 0" xyz="0 -0.05 0" />
            <geometry>
                <box size ="0.120 0.020 0.08"/>
            </geometry>
            <material name="red"/>

        </visual>

        <collision>
            <origin rpy="0 0 0" xyz="0 -0.05 0" />
            <geometry>
                <box size ="0.120 0.020 0.08"/>
            </geometry>
          </collision>

    </link>

    <joint name="link_03__link_04" type="revolute">
        <axis xyz="0 0 1"/>

        <safety_controller k_position="100.0" k_velocity="40.0" soft_lower_limit="-2.818" soft_upper_limit="2.818" />

        <limit effort="1000.0" lower="-2.87" upper="2.87" velocity="0.5"/>
        <origin rpy="1.57 0 0" xyz="0.068 0 0"/>
        <parent link="link_03"/>
        <child link="link_04"/>
    </joint>

    <link name="link_04">

        <inertial>
            <mass value="0.9"/>
            <origin rpy="0 0 0" xyz="-0.0360446 0.0336853 0.031882"/>
            <inertia ixx="0.00799663881132" ixy="0.0" ixz="0.0" iyy="0.00825390705278" iyz="0.0" izz="0.0102515004345"/>
        </inertial>
        <visual>
            <origin rpy="0 0 0" xyz="0 0 0.0455" />
            <geometry>
                <cylinder radius="0.018" length="0.091" />
            </geometry>

            <material name="white"/>

        </visual>

        <collision>
             <origin rpy="0 0 0" xyz="0 0 0.0455" />
            <geometry>
                <cylinder radius="0.018" length="0.091" />
            </geometry>

          </collision>

        <visual>
            <origin rpy="0 0 0" xyz="0 0 0.135" />
            <geometry>
                <box size ="0.06 0.078 0.088"/>
            </geometry>
            <material name="white"/>

        </visual>

        <collision>
            <origin rpy="0 0 0" xyz="0 0 0.135" />
            <geometry>
                <box size ="0.06 0.078 0.088"/>
            </geometry>
          </collision>

        <visual>
            <origin rpy="0 0 0" xyz="0 0.042 0.181" />
            <geometry>
                <box size ="0.06 0.006 0.18"/>
            </geometry>
            <material name="white"/>
        </visual>

        <collision>
            <origin rpy="0 0 0" xyz="0 0.042 0.181" />
            <geometry>
                <box size ="0.06 0.006 0.18"/>
            </geometry>
          </collision>

        <visual>
            <origin rpy="0 0 0" xyz="0 -0.042 0.181" />
            <geometry>
                <box size ="0.06 0.006 0.18"/>
            </geometry>
            <material name="white"/>
        </visual>

        <collision>
            <origin rpy="0 0 0" xyz="0 -0.042 0.181" />
            <geometry>
                <box size ="0.06 0.006 0.18"/>
            </geometry>
          </collision>

        <visual>
            <origin rpy="1.57 0 0" xyz="0 0.042 0.271" />
            <geometry>
                <cylinder radius="0.03" length="0.006" />
            </geometry>
            <material name="white"/>
        </visual>

        <collision>
            <origin rpy="1.57 0 0" xyz="0 0.042 0.271" />
            <geometry>
                <cylinder radius="0.03" length="0.006" />
            </geometry>
          </collision>

        <visual>
            <origin rpy="1.57 0 0" xyz="0 -0.042 0.271" />
            <geometry>
                <cylinder radius="0.03" length="0.006" />
            </geometry>

            <material name="white"/>

        </visual>

        <collision>
            <origin rpy="1.57 0 0" xyz="0 -0.042 0.271" />
            <geometry>
                <cylinder radius="0.03" length="0.006" />
            </geometry>
          </collision>

    </link>

    <joint name="link_04__link_04_red" type="fixed">
        <origin rpy="0 0 0" xyz="0 0 0.181"/>
        <parent link="link_04"/>
        <child link="link_04_red"/>
    </joint>

    <link name="link_04_red">

       <visual>
            <origin rpy="0 1.57 0" xyz="0 0.055 0" />
            <geometry>
                <box size ="0.18 0.020 0.06"/>
            </geometry>
            <material name="red"/>

        </visual>

        <collision>
            <origin rpy="0 1.57 0" xyz="0 0.055 0" />
            <geometry>
                <box size ="0.18 0.020 0.06"/>
            </geometry>
          </collision>

        <visual>
            <origin rpy="0 1.57 0" xyz="0 -0.055 0" />
            <geometry>
                <box size ="0.18 0.020 0.06"/>
            </geometry>
            <material name="red"/>

        </visual>

        <collision>
            <origin rpy="0 1.57 0" xyz="0 -0.055 0" />
            <geometry>
                <box size ="0.18 0.020 0.06"/>
            </geometry>
          </collision>

        <visual>
            <origin rpy="1.57 0 0" xyz="0 -0.055 0.09" />
            <geometry>
                <cylinder radius="0.03" length="0.02" />
            </geometry>
            <material name="red"/>
        </visual>

        <collision>
            <origin rpy="1.57 0 0" xyz="0 -0.055 0.09" />
            <geometry>
                <cylinder radius="0.03" length="0.02" />
            </geometry>
          </collision>

        <visual>
            <origin rpy="1.57 0 0" xyz="0 0.055 0.09" />
            <geometry>
                <cylinder radius="0.03" length="0.02" />
            </geometry>
             <material name="red"/>
        </visual>

        <collision>
            <origin rpy="1.57 0 0" xyz="0 0.055 0.09" />
            <geometry>
                <cylinder radius="0.03" length="0.02" />
            </geometry>
          </collision>

    </link>

    <joint name="link_04__link_05" type="revolute">
        <axis xyz="0 0 1"/>

        <safety_controller k_position="100.0" k_velocity="40.0" soft_lower_limit="-2.388" soft_upper_limit="2.388" />

        <limit effort="1000.0" lower="-2.44" upper="2.44" velocity="0.5"/>
        <origin rpy="-1.57 0 0" xyz="0 0 0.271"/>
        <parent link="link_04"/>
        <child link="link_05"/>
    </joint>

    <link name="link_05">

        <inertial>
            <mass value="0.7"/>
            <origin rpy="0 0 0" xyz="0 0.0610427 -0.104176"/>
            <inertia ixx="0.030371374513" ixy="0.0" ixz="0.0" iyy="0.0288752887402" iyz="-0.0" izz="0.02"/>
        </inertial>
        <visual>
            <origin rpy="0 0 0" xyz="0 0 0" />
            <geometry>
                <cylinder radius="0.0175" length="0.078" />
            </geometry>

            <material name="white"/>
        </visual>

        <collision>
            <origin rpy="0 0 0" xyz="0 0 0" />
            <geometry>
                <cylinder radius="0.0175" length="0.078" />
            </geometry>
          </collision>

        <visual>
            <origin rpy="0 0 0" xyz="0 0 0.0355" />
            <geometry>
                <box size ="0.055 0.1 0.007"/>
            </geometry>
            <material name="white"/>
        </visual>

        <collision>
            <origin rpy="0 0 0" xyz="0 0 0.0355" />
            <geometry>
                <box size ="0.055 0.1 0.007"/>
            </geometry>
          </collision>

        <visual>
            <origin rpy="0 0 0" xyz="0 0 -0.0355" />
            <geometry>
                <box size ="0.055 0.1 0.007"/>
            </geometry>
            <material name="white"/>

        </visual>

        <collision>
            <origin rpy="0 0 0" xyz="0 0 -0.0355" />
            <geometry>
                <box size ="0.055 0.1 0.007"/>
            </geometry>
          </collision>

        <visual>
            <origin rpy="0 0 0" xyz="0 -0.0465 0" />
            <geometry>
                <box size ="0.055 0.007 0.078"/>
            </geometry>
            <material name="white"/>

        </visual>

        <collision>
            <origin rpy="0 0 0" xyz="0 -0.0465 0" />
            <geometry>
                <box size ="0.055 0.007 0.078"/>
            </geometry>
          </collision>

    </link>

    <joint name="link_05__link_05_red" type="fixed">
        <origin rpy="0 0 0" xyz="0 0.05 0"/>
        <parent link="link_05"/>
        <child link="link_05_red"/>
    </joint>

    <link name="link_05_red">

       <visual>
            <origin rpy="0 0 0" xyz="0 -0.00075 0" />
            <geometry>
                <box size ="0.055 0.0015 0.078"/>
            </geometry>
            <material name="red"/>

        </visual>

        <collision>
            <origin rpy="0 0 0" xyz="0 -0.00075 0" />
            <geometry>
                <box size ="0.055 0.0015 0.078"/>
            </geometry>
          </collision>

        <visual>
            <origin rpy="0 0 0" xyz="0.02675 -0.05 0" />
            <geometry>
                <box size ="0.0015 0.1 0.078"/>
            </geometry>
            <material name="red"/>

        </visual>

        <collision>
            <origin rpy="0 0 0" xyz="0.02675 -0.05 0" />
            <geometry>
                <box size ="0.0015 0.1 0.078"/>
            </geometry>
          </collision>

        <visual>
            <origin rpy="0 0 0" xyz="-0.02675 -0.05 0" />
            <geometry>
                <box size ="0.0015 0.1 0.078"/>
            </geometry>
            <material name="red"/>

        </visual>

        <collision>
            <origin rpy="0 0 0" xyz="-0.02675 -0.05 0" />
            <geometry>
                <box size ="0.0015 0.1 0.078"/>
            </geometry>
          </collision>

    </link>

    <joint name="link_05__link_06" type="revolute">
        <axis xyz="0 0 1"/>

        <safety_controller k_position="100.0" k_velocity="40.0" soft_lower_limit="-3.12" soft_upper_limit="3.12" />

        <limit effort="1000.0" lower="-3.14" upper="3.14" velocity="0.5"/>
        <origin rpy="1.57 0 0" xyz="0 -0.0766 0"/>
        <parent link="link_05"/>
        <child link="link_06"/>
    </joint>

    <link name="link_06">

        <inertial>
            <mass value="0.5"/>
            <origin rpy="0 0 0" xyz="0.0510509 0.009108 0.0106343"/>
           <inertia ixx="0.00303336450376" ixy="-0.000437276865508" ixz="0.000629257294877" iyy="0.00404479911567" iyz="0.000130472021025" izz="0.00558234286039"/>
        </inertial>
        <visual>
            <origin rpy="0 0 0" xyz="0 0 -0.0159" />
            <geometry>
                <cylinder radius="0.0095" length="0.0168" />
            </geometry>
            <material name="white"/>
        </visual>

        <collision>
            <origin rpy="0 0 0" xyz="0 0 -0.0159" />
            <geometry>
                <cylinder radius="0.0095" length="0.0168" />
            </geometry>

          </collision>

        <visual>
            <origin rpy="0 0 0" xyz="0 0 -0.005" />
            <geometry>
                <cylinder radius="0.024" length="0.005" />
            </geometry>
            <material name="white"/>

        </visual>

        <collision>
            <origin rpy="0 0 0" xyz="0 0 -0.005" />
            <geometry>
                <cylinder radius="0.024" length="0.005" />
            </geometry>

          </collision>
    </link>






 <!-- ////////////////////////////////////////////// -->

    <joint name="link_06__link_hand_cyl" type="fixed">
        <origin rpy="0 0 0" xyz="0 0 0"/>
        <parent link="link_06"/>
        <child link="link_hand_cyl"/>
    </joint>

    <link name="link_hand_cyl">

         <inertial>
            <mass value="0.01"/>
            <origin rpy="0 0 0" xyz="0.0510509 0.009108 0.0106343"/>
           <inertia ixx="0.00303336450376" ixy="-0.000437276865508" ixz="0.000629257294877" iyy="0.00404479911567" iyz="0.000130472021025" izz="0.00558234286039"/>
        </inertial>


        <visual>
            <origin rpy="0 0 1.57" xyz="0 0 0"/>
            <geometry>
                <mesh filename="file://$(find ruka_gz)/config/mesh/gripper4310.stl"/>
            </geometry>
            <material name="blue"/>
        </visual>

        <collision>
            <origin rpy="0 0 0" xyz="0 0 0.01" />
            <geometry>
                <cylinder radius="0.010" length="0.01" />
            </geometry>

          </collision>


    </link>

    <joint name="link_hand_cyl__first_fin" type="prismatic">
        <parent link="link_hand_cyl" />
        <child link="first_fin" />
        <origin rpy="1.57 0 3.14" xyz="0 0.005 0.0642" />
        <axis xyz="0 0 1" />
        <limit effort="20" lower="0.0" upper="0.01" velocity="0.2" />
    </joint>


    <link name="first_fin">

         <inertial>
            <mass value="0.01"/>
            <origin rpy="0 0 0" xyz="0.0510509 0.009108 0.0106343"/>
           <inertia ixx="0.00303336450376" ixy="-0.000437276865508" ixz="0.000629257294877" iyy="0.00404479911567" iyz="0.000130472021025" izz="0.00558234286039"/>
        </inertial>


        <visual>
            <origin rpy="0 0 0" xyz="0 0 0"/>
            <geometry>
                <mesh filename="file://$(find ruka_gz)/config/mesh/finger50mm-S.stl"/>
            </geometry>
            <material name="white"/>
        </visual>

        <collision>
            <origin rpy="0 0 0" xyz="0 0 0" />
            <geometry>
                <mesh filename="file://$(find ruka_gz)/config/mesh/finger50mm-S.stl" />
            </geometry>
        </collision>


    </link>


     <joint name="link_hand_cyl__second_fin" type="prismatic">
        <parent link="link_hand_cyl" />
        <child link="second_fin" />
        <origin rpy="1.57 0 0" xyz="0 -0.005 0.0642" />
        <axis xyz="0 0 1" />
        <limit effort="20" lower="0.0" upper="0.01" velocity="0.2" />
    </joint>


    <link name="second_fin">

         <inertial>
            <mass value="0.01"/>
            <origin rpy="0 0 0" xyz="0.0510509 0.009108 0.0106343"/>
           <inertia ixx="0.00303336450376" ixy="-0.000437276865508" ixz="0.000629257294877" iyy="0.00404479911567" iyz="0.000130472021025" izz="0.00558234286039"/>
        </inertial>


        <visual>
            <origin rpy="0 0 0" xyz="0 0 0"/>
            <geometry>
                <mesh filename="file://$(find ruka_gz)/config/mesh/finger50mm-S-1.stl"/>
            </geometry>
            <material name="white"/>
        </visual>

        <collision>
            <origin rpy="0 0 0" xyz="0 0 0" />
            <geometry>
                <mesh filename="file://$(find ruka_gz)/config/mesh/finger50mm-S-1.stl" />
            </geometry>
        </collision>


    </link>




</robot>
